2025-05-19 10:29:04,166 [DEBUG] py4...: Calling cytoscape_ping()
2025-05-19 10:29:04,166 [DEBUG] py4...: ǀCalling cytoscape_version_info(base_url='http://127.0.0.1:1234/v1')
2025-05-19 10:29:04,166 [DEBUG] py4...: ǀǀCalling cyrest_get('version', base_url='http://127.0.0.1:1234/v1')
2025-05-19 10:29:04,166 [DEBUG] py4...: Attempting to direct connect to Cytoscape on http://127.0.0.1:1234/v1
2025-05-19 10:29:04,168 [DEBUG] py4...: Attempting to connect to remote Cytoscape because of error HTTPConnectionPool(host='127.0.0.1', port=1234): Max retries exceeded with url: /v1 (Caused by NewConnectionError('<urllib3.connection.HTTPConnection object at 0x776aba19c640>: Failed to establish a new connection: [Errno 111] Connection refused'))
2025-05-19 10:29:04,168 [DEBUG] py4...: ǀǀHTTP GET(http://127.0.0.1:1234/v1)
2025-05-19 10:29:04,689 [DEBUG] py4...: Error initially contacting Jupyter-bridge: Error posting to Jupyter-bridge: Channel None:request contains unprocessed message
2025-05-19 10:29:04,689 [DEBUG] py4...: ǀǀ'cyrest_get' exception RequestException('Cannot find local or remote Cytoscape. Start Cytoscape and then proceed.')
2025-05-19 10:29:04,689 [DEBUG] py4...: ǀ'cytoscape_version_info' exception RequestException('Cannot find local or remote Cytoscape. Start Cytoscape and then proceed.')
2025-05-19 10:29:04,689 [DEBUG] py4...: 'cytoscape_ping' exception RequestException('Cannot find local or remote Cytoscape. Start Cytoscape and then proceed.')
2025-05-19 10:29:04,689 [DEBUG] py4...: --------------------
