2025-05-19 10:29:04,166 [DEBUG] py4...: Calling cytoscape_ping()
2025-05-19 10:29:04,166 [DEBUG] py4...: ǀCalling cytoscape_version_info(base_url='http://127.0.0.1:1234/v1')
2025-05-19 10:29:04,166 [DEBUG] py4...: ǀǀCalling cyrest_get('version', base_url='http://127.0.0.1:1234/v1')
2025-05-19 10:29:04,166 [DEBUG] py4...: Attempting to direct connect to Cytoscape on http://127.0.0.1:1234/v1
2025-05-19 10:29:04,168 [DEBUG] py4...: Attempting to connect to remote Cytoscape because of error HTTPConnectionPool(host='127.0.0.1', port=1234): Max retries exceeded with url: /v1 (Caused by NewConnectionError('<urllib3.connection.HTTPConnection object at 0x776aba19c640>: Failed to establish a new connection: [Errno 111] Connection refused'))
2025-05-19 10:29:04,168 [DEBUG] py4...: ǀǀHTTP GET(http://127.0.0.1:1234/v1)
2025-05-19 10:29:04,689 [DEBUG] py4...: Error initially contacting Jupyter-bridge: Error posting to Jupyter-bridge: Channel None:request contains unprocessed message
2025-05-19 10:29:04,689 [DEBUG] py4...: ǀǀ'cyrest_get' exception RequestException('Cannot find local or remote Cytoscape. Start Cytoscape and then proceed.')
2025-05-19 10:29:04,689 [DEBUG] py4...: ǀ'cytoscape_version_info' exception RequestException('Cannot find local or remote Cytoscape. Start Cytoscape and then proceed.')
2025-05-19 10:29:04,689 [DEBUG] py4...: 'cytoscape_ping' exception RequestException('Cannot find local or remote Cytoscape. Start Cytoscape and then proceed.')
2025-05-19 10:29:04,689 [DEBUG] py4...: --------------------
2025-05-19 10:36:40,174 [DEBUG] py4...: Calling cytoscape_ping()
2025-05-19 10:36:40,175 [DEBUG] py4...: ǀCalling cytoscape_version_info(base_url='http://127.0.0.1:1234/v1')
2025-05-19 10:36:40,175 [DEBUG] py4...: ǀǀCalling cyrest_get('version', base_url='http://127.0.0.1:1234/v1')
2025-05-19 10:36:40,175 [DEBUG] py4...: Attempting to direct connect to Cytoscape on http://127.0.0.1:1234/v1
2025-05-19 10:36:40,175 [DEBUG] py4...: Attempting to connect to remote Cytoscape because of error HTTPConnectionPool(host='127.0.0.1', port=1234): Max retries exceeded with url: /v1 (Caused by NewConnectionError('<urllib3.connection.HTTPConnection object at 0x7f73ad855410>: Failed to establish a new connection: [Errno 111] Connection refused'))
2025-05-19 10:36:40,175 [DEBUG] py4...: ǀǀHTTP GET(http://127.0.0.1:1234/v1)
2025-05-19 10:36:40,599 [DEBUG] py4...: Error initially contacting Jupyter-bridge: Error posting to Jupyter-bridge: Channel None:request contains unprocessed message
2025-05-19 10:36:40,599 [DEBUG] py4...: ǀǀ'cyrest_get' exception RequestException('Cannot find local or remote Cytoscape. Start Cytoscape and then proceed.')
2025-05-19 10:36:40,599 [DEBUG] py4...: ǀ'cytoscape_version_info' exception RequestException('Cannot find local or remote Cytoscape. Start Cytoscape and then proceed.')
2025-05-19 10:36:40,599 [DEBUG] py4...: 'cytoscape_ping' exception RequestException('Cannot find local or remote Cytoscape. Start Cytoscape and then proceed.')
2025-05-19 10:36:40,599 [DEBUG] py4...: --------------------
2025-05-19 10:37:03,433 [DEBUG] py4...: Calling cytoscape_ping()
2025-05-19 10:37:03,433 [DEBUG] py4...: ǀCalling cytoscape_version_info(base_url='http://127.0.0.1:1234/v1')
2025-05-19 10:37:03,433 [DEBUG] py4...: ǀǀCalling cyrest_get('version', base_url='http://127.0.0.1:1234/v1')
2025-05-19 10:37:03,433 [DEBUG] py4...: Attempting to direct connect to Cytoscape on http://127.0.0.1:1234/v1
2025-05-19 10:37:03,477 [DEBUG] py4...: Detected py4cytoscape running on Cytoscape workstation
2025-05-19 10:37:03,478 [DEBUG] py4...: ǀǀHTTP GET(http://127.0.0.1:1234/v1/version)
2025-05-19 10:37:03,483 [DEBUG] py4...: ǀǀOK[200], content: {"apiVersion":"v1","cytoscapeVersion":"3.10.3"}
2025-05-19 10:37:03,483 [DEBUG] py4...: ǀǀReturning 'cyrest_get': {'apiVersion': 'v1', 'cytoscapeVersion': '3.10.3'}
2025-05-19 10:37:03,483 [DEBUG] py4...: ǀReturning 'cytoscape_version_info': {'apiVersion': 'v1', 'cytoscapeVersion': '3.10.3', 'automationAPIVersion': '1.12.0', 'py4cytoscapeVersion': '1.12.0'}
2025-05-19 10:37:03,483 [DEBUG] py4...: Returning 'cytoscape_ping': 'You are connected to Cytoscape!'
2025-05-19 10:37:03,483 [DEBUG] py4...: --------------------
2025-05-19 10:37:03,483 [DEBUG] py4...: Calling import_network_from_file('WP3657.gpml')
2025-05-19 10:37:03,483 [DEBUG] py4...: ǀCalling commands_post('network load file file="/mnt/data1/ttdemo/WP3657.gpml"', base_url='http://127.0.0.1:1234/v1')
2025-05-19 10:37:03,483 [DEBUG] py4...: ǀHTTP POST(http://127.0.0.1:1234/v1/commands/network/load%20file), json: {'file': '/mnt/data1/ttdemo/WP3657.gpml'}
2025-05-19 10:37:03,610 [DEBUG] py4...: ǀInternal Server Error[500], content: {
 "data": {},
 "errors":[{"status":500,"type":"urn:cytoscape:ci:cyrest-core:v1:handle-json-command:errors:2","message":"Pathway not available -- invalid GPML","link":"file:/home/john/CytoscapeConfiguration/3/framework-cytoscape.log"}]
}
2025-05-19 10:37:03,610 [DEBUG] py4...: ǀ'commands_post' exception CyError('In commands_post(): Pathway not available -- invalid GPML')
2025-05-19 10:37:03,610 [DEBUG] py4...: 'import_network_from_file' exception CyError('In commands_post(): Pathway not available -- invalid GPML')
2025-05-19 10:37:03,610 [DEBUG] py4...: --------------------
2025-05-19 10:40:31,404 [DEBUG] py4...: Calling cytoscape_ping()
2025-05-19 10:40:31,404 [DEBUG] py4...: ǀCalling cytoscape_version_info(base_url='http://127.0.0.1:1234/v1')
2025-05-19 10:40:31,404 [DEBUG] py4...: ǀǀCalling cyrest_get('version', base_url='http://127.0.0.1:1234/v1')
2025-05-19 10:40:31,404 [DEBUG] py4...: Attempting to direct connect to Cytoscape on http://127.0.0.1:1234/v1
2025-05-19 10:40:31,410 [DEBUG] py4...: Detected py4cytoscape running on Cytoscape workstation
2025-05-19 10:40:31,410 [DEBUG] py4...: ǀǀHTTP GET(http://127.0.0.1:1234/v1/version)
2025-05-19 10:40:31,413 [DEBUG] py4...: ǀǀOK[200], content: {"apiVersion":"v1","cytoscapeVersion":"3.10.3"}
2025-05-19 10:40:31,413 [DEBUG] py4...: ǀǀReturning 'cyrest_get': {'apiVersion': 'v1', 'cytoscapeVersion': '3.10.3'}
2025-05-19 10:40:31,413 [DEBUG] py4...: ǀReturning 'cytoscape_version_info': {'apiVersion': 'v1', 'cytoscapeVersion': '3.10.3', 'automationAPIVersion': '1.12.0', 'py4cytoscapeVersion': '1.12.0'}
2025-05-19 10:40:31,414 [DEBUG] py4...: Returning 'cytoscape_ping': 'You are connected to Cytoscape!'
2025-05-19 10:40:31,414 [DEBUG] py4...: --------------------
2025-05-19 10:40:31,414 [DEBUG] py4...: Calling import_network_from_file('toxindex/pathway_visualization/WP3657.gpml')
2025-05-19 10:40:31,414 [DEBUG] py4...: ǀCalling commands_post('network load file file="/mnt/data1/ttdemo/toxindex/pathway_visualization/WP3657.gpml"', base_url='http://127.0.0.1:1234/v1')
2025-05-19 10:40:31,414 [DEBUG] py4...: ǀHTTP POST(http://127.0.0.1:1234/v1/commands/network/load%20file), json: {'file': '/mnt/data1/ttdemo/toxindex/pathway_visualization/WP3657.gpml'}
2025-05-19 10:40:31,452 [DEBUG] py4...: ǀInternal Server Error[500], content: {
 "data": {},
 "errors":[{"status":500,"type":"urn:cytoscape:ci:cyrest-core:v1:handle-json-command:errors:2","message":"Pathway not available -- invalid GPML","link":"file:/home/john/CytoscapeConfiguration/3/framework-cytoscape.log"}]
}
2025-05-19 10:40:31,452 [DEBUG] py4...: ǀ'commands_post' exception CyError('In commands_post(): Pathway not available -- invalid GPML')
2025-05-19 10:40:31,452 [DEBUG] py4...: 'import_network_from_file' exception CyError('In commands_post(): Pathway not available -- invalid GPML')
2025-05-19 10:40:31,452 [DEBUG] py4...: --------------------
2025-05-19 10:42:12,690 [DEBUG] py4...: Calling cytoscape_ping()
2025-05-19 10:42:12,690 [DEBUG] py4...: ǀCalling cytoscape_version_info(base_url='http://127.0.0.1:1234/v1')
2025-05-19 10:42:12,690 [DEBUG] py4...: ǀǀCalling cyrest_get('version', base_url='http://127.0.0.1:1234/v1')
2025-05-19 10:42:12,690 [DEBUG] py4...: Attempting to direct connect to Cytoscape on http://127.0.0.1:1234/v1
2025-05-19 10:42:12,695 [DEBUG] py4...: Detected py4cytoscape running on Cytoscape workstation
2025-05-19 10:42:12,695 [DEBUG] py4...: ǀǀHTTP GET(http://127.0.0.1:1234/v1/version)
2025-05-19 10:42:12,699 [DEBUG] py4...: ǀǀOK[200], content: {"apiVersion":"v1","cytoscapeVersion":"3.10.3"}
2025-05-19 10:42:12,699 [DEBUG] py4...: ǀǀReturning 'cyrest_get': {'apiVersion': 'v1', 'cytoscapeVersion': '3.10.3'}
2025-05-19 10:42:12,699 [DEBUG] py4...: ǀReturning 'cytoscape_version_info': {'apiVersion': 'v1', 'cytoscapeVersion': '3.10.3', 'automationAPIVersion': '1.12.0', 'py4cytoscapeVersion': '1.12.0'}
2025-05-19 10:42:12,699 [DEBUG] py4...: Returning 'cytoscape_ping': 'You are connected to Cytoscape!'
2025-05-19 10:42:12,699 [DEBUG] py4...: --------------------
2025-05-19 10:42:12,699 [DEBUG] py4...: Calling import_network_from_file('toxindex/pathway_visualization/WP3657.gpml')
2025-05-19 10:42:12,699 [DEBUG] py4...: ǀCalling commands_post('network load file file="/mnt/data1/ttdemo/toxindex/pathway_visualization/WP3657.gpml"', base_url='http://127.0.0.1:1234/v1')
2025-05-19 10:42:12,699 [DEBUG] py4...: ǀHTTP POST(http://127.0.0.1:1234/v1/commands/network/load%20file), json: {'file': '/mnt/data1/ttdemo/toxindex/pathway_visualization/WP3657.gpml'}
2025-05-19 10:42:12,733 [DEBUG] py4...: ǀInternal Server Error[500], content: {
 "data": {},
 "errors":[{"status":500,"type":"urn:cytoscape:ci:cyrest-core:v1:handle-json-command:errors:2","message":"Pathway not available -- invalid GPML","link":"file:/home/john/CytoscapeConfiguration/3/framework-cytoscape.log"}]
}
2025-05-19 10:42:12,733 [DEBUG] py4...: ǀ'commands_post' exception CyError('In commands_post(): Pathway not available -- invalid GPML')
2025-05-19 10:42:12,733 [DEBUG] py4...: 'import_network_from_file' exception CyError('In commands_post(): Pathway not available -- invalid GPML')
2025-05-19 10:42:12,733 [DEBUG] py4...: --------------------
